2018-01-01 15:29:21,033 ERROR: Exception on /edit_profile [POST] [in /home/zetdg/Devasoft/devablog/.devablog/lib/python3.5/site-packages/flask/app.py:1560]
Traceback (most recent call last):
  File "/home/zetdg/Devasoft/devablog/.devablog/lib/python3.5/site-packages/flask/app.py", line 1982, in wsgi_app
    response = self.full_dispatch_request()
  File "/home/zetdg/Devasoft/devablog/.devablog/lib/python3.5/site-packages/flask/app.py", line 1614, in full_dispatch_request
    rv = self.handle_user_exception(e)
  File "/home/zetdg/Devasoft/devablog/.devablog/lib/python3.5/site-packages/flask/app.py", line 1517, in handle_user_exception
    reraise(exc_type, exc_value, tb)
  File "/home/zetdg/Devasoft/devablog/.devablog/lib/python3.5/site-packages/flask/_compat.py", line 33, in reraise
    raise value
  File "/home/zetdg/Devasoft/devablog/.devablog/lib/python3.5/site-packages/flask/app.py", line 1612, in full_dispatch_request
    rv = self.dispatch_request()
  File "/home/zetdg/Devasoft/devablog/.devablog/lib/python3.5/site-packages/flask/app.py", line 1598, in dispatch_request
    return self.view_functions[rule.endpoint](**req.view_args)
  File "/home/zetdg/Devasoft/devablog/.devablog/lib/python3.5/site-packages/flask_login/utils.py", line 261, in decorated_view
    return func(*args, **kwargs)
  File "/home/zetdg/Devasoft/devablog/app/routes.py", line 180, in edit_profile
    return render_template(url_for('index'), username=current_user.username)
  File "/home/zetdg/Devasoft/devablog/.devablog/lib/python3.5/site-packages/flask/templating.py", line 133, in render_template
    return _render(ctx.app.jinja_env.get_or_select_template(template_name_or_list),
  File "/home/zetdg/Devasoft/devablog/.devablog/lib/python3.5/site-packages/jinja2/environment.py", line 869, in get_or_select_template
    return self.get_template(template_name_or_list, parent, globals)
  File "/home/zetdg/Devasoft/devablog/.devablog/lib/python3.5/site-packages/jinja2/environment.py", line 830, in get_template
    return self._load_template(name, self.make_globals(globals))
  File "/home/zetdg/Devasoft/devablog/.devablog/lib/python3.5/site-packages/jinja2/environment.py", line 804, in _load_template
    template = self.loader.load(self, name, globals)
  File "/home/zetdg/Devasoft/devablog/.devablog/lib/python3.5/site-packages/jinja2/loaders.py", line 113, in load
    source, filename, uptodate = self.get_source(environment, name)
  File "/home/zetdg/Devasoft/devablog/.devablog/lib/python3.5/site-packages/flask/templating.py", line 57, in get_source
    return self._get_source_fast(environment, template)
  File "/home/zetdg/Devasoft/devablog/.devablog/lib/python3.5/site-packages/flask/templating.py", line 85, in _get_source_fast
    raise TemplateNotFound(template)
jinja2.exceptions.TemplateNotFound: /index
2018-01-01 15:29:34,242 INFO: Devablog startup [in /home/zetdg/Devasoft/devablog/app/__init__.py:61]
2018-01-01 15:29:39,895 ERROR: Exception on /edit_profile [POST] [in /home/zetdg/Devasoft/devablog/.devablog/lib/python3.5/site-packages/flask/app.py:1560]
Traceback (most recent call last):
  File "/home/zetdg/Devasoft/devablog/.devablog/lib/python3.5/site-packages/flask/app.py", line 1982, in wsgi_app
    response = self.full_dispatch_request()
  File "/home/zetdg/Devasoft/devablog/.devablog/lib/python3.5/site-packages/flask/app.py", line 1614, in full_dispatch_request
    rv = self.handle_user_exception(e)
  File "/home/zetdg/Devasoft/devablog/.devablog/lib/python3.5/site-packages/flask/app.py", line 1517, in handle_user_exception
    reraise(exc_type, exc_value, tb)
  File "/home/zetdg/Devasoft/devablog/.devablog/lib/python3.5/site-packages/flask/_compat.py", line 33, in reraise
    raise value
  File "/home/zetdg/Devasoft/devablog/.devablog/lib/python3.5/site-packages/flask/app.py", line 1612, in full_dispatch_request
    rv = self.dispatch_request()
  File "/home/zetdg/Devasoft/devablog/.devablog/lib/python3.5/site-packages/flask/app.py", line 1598, in dispatch_request
    return self.view_functions[rule.endpoint](**req.view_args)
  File "/home/zetdg/Devasoft/devablog/.devablog/lib/python3.5/site-packages/flask_login/utils.py", line 261, in decorated_view
    return func(*args, **kwargs)
  File "/home/zetdg/Devasoft/devablog/app/routes.py", line 180, in edit_profile
    return render_template(url_for('user'), username=current_user.username)
  File "/home/zetdg/Devasoft/devablog/.devablog/lib/python3.5/site-packages/flask/helpers.py", line 333, in url_for
    return appctx.app.handle_url_build_error(error, endpoint, values)
  File "/home/zetdg/Devasoft/devablog/.devablog/lib/python3.5/site-packages/flask/app.py", line 1805, in handle_url_build_error
    reraise(exc_type, exc_value, tb)
  File "/home/zetdg/Devasoft/devablog/.devablog/lib/python3.5/site-packages/flask/_compat.py", line 33, in reraise
    raise value
  File "/home/zetdg/Devasoft/devablog/.devablog/lib/python3.5/site-packages/flask/helpers.py", line 323, in url_for
    force_external=external)
  File "/home/zetdg/Devasoft/devablog/.devablog/lib/python3.5/site-packages/werkzeug/routing.py", line 1768, in build
    raise BuildError(endpoint, values, method, self)
werkzeug.routing.BuildError: Could not build url for endpoint 'user'. Did you forget to specify values ['username']?
2018-01-01 15:30:01,110 INFO: Devablog startup [in /home/zetdg/Devasoft/devablog/app/__init__.py:61]
2018-01-01 15:30:06,267 ERROR: Exception on /edit_profile [POST] [in /home/zetdg/Devasoft/devablog/.devablog/lib/python3.5/site-packages/flask/app.py:1560]
Traceback (most recent call last):
  File "/home/zetdg/Devasoft/devablog/.devablog/lib/python3.5/site-packages/flask/app.py", line 1982, in wsgi_app
    response = self.full_dispatch_request()
  File "/home/zetdg/Devasoft/devablog/.devablog/lib/python3.5/site-packages/flask/app.py", line 1614, in full_dispatch_request
    rv = self.handle_user_exception(e)
  File "/home/zetdg/Devasoft/devablog/.devablog/lib/python3.5/site-packages/flask/app.py", line 1517, in handle_user_exception
    reraise(exc_type, exc_value, tb)
  File "/home/zetdg/Devasoft/devablog/.devablog/lib/python3.5/site-packages/flask/_compat.py", line 33, in reraise
    raise value
  File "/home/zetdg/Devasoft/devablog/.devablog/lib/python3.5/site-packages/flask/app.py", line 1612, in full_dispatch_request
    rv = self.dispatch_request()
  File "/home/zetdg/Devasoft/devablog/.devablog/lib/python3.5/site-packages/flask/app.py", line 1598, in dispatch_request
    return self.view_functions[rule.endpoint](**req.view_args)
  File "/home/zetdg/Devasoft/devablog/.devablog/lib/python3.5/site-packages/flask_login/utils.py", line 261, in decorated_view
    return func(*args, **kwargs)
  File "/home/zetdg/Devasoft/devablog/app/routes.py", line 180, in edit_profile
    return render_template(url_for('user', username=current_user.username))
  File "/home/zetdg/Devasoft/devablog/.devablog/lib/python3.5/site-packages/flask/templating.py", line 133, in render_template
    return _render(ctx.app.jinja_env.get_or_select_template(template_name_or_list),
  File "/home/zetdg/Devasoft/devablog/.devablog/lib/python3.5/site-packages/jinja2/environment.py", line 869, in get_or_select_template
    return self.get_template(template_name_or_list, parent, globals)
  File "/home/zetdg/Devasoft/devablog/.devablog/lib/python3.5/site-packages/jinja2/environment.py", line 830, in get_template
    return self._load_template(name, self.make_globals(globals))
  File "/home/zetdg/Devasoft/devablog/.devablog/lib/python3.5/site-packages/jinja2/environment.py", line 804, in _load_template
    template = self.loader.load(self, name, globals)
  File "/home/zetdg/Devasoft/devablog/.devablog/lib/python3.5/site-packages/jinja2/loaders.py", line 113, in load
    source, filename, uptodate = self.get_source(environment, name)
  File "/home/zetdg/Devasoft/devablog/.devablog/lib/python3.5/site-packages/flask/templating.py", line 57, in get_source
    return self._get_source_fast(environment, template)
  File "/home/zetdg/Devasoft/devablog/.devablog/lib/python3.5/site-packages/flask/templating.py", line 85, in _get_source_fast
    raise TemplateNotFound(template)
jinja2.exceptions.TemplateNotFound: /user/ze
2018-01-01 15:30:26,479 INFO: Devablog startup [in /home/zetdg/Devasoft/devablog/app/__init__.py:61]
