2017-12-31 19:02:01,519 ERROR: Exception on /follow/winne [GET] [in /home/zetdg/Devasoft/devablog/.devablog/lib/python3.5/site-packages/flask/app.py:1560]
Traceback (most recent call last):
  File "/home/zetdg/Devasoft/devablog/.devablog/lib/python3.5/site-packages/flask/app.py", line 1982, in wsgi_app
    response = self.full_dispatch_request()
  File "/home/zetdg/Devasoft/devablog/.devablog/lib/python3.5/site-packages/flask/app.py", line 1614, in full_dispatch_request
    rv = self.handle_user_exception(e)
  File "/home/zetdg/Devasoft/devablog/.devablog/lib/python3.5/site-packages/flask/app.py", line 1517, in handle_user_exception
    reraise(exc_type, exc_value, tb)
  File "/home/zetdg/Devasoft/devablog/.devablog/lib/python3.5/site-packages/flask/_compat.py", line 33, in reraise
    raise value
  File "/home/zetdg/Devasoft/devablog/.devablog/lib/python3.5/site-packages/flask/app.py", line 1612, in full_dispatch_request
    rv = self.dispatch_request()
  File "/home/zetdg/Devasoft/devablog/.devablog/lib/python3.5/site-packages/flask/app.py", line 1598, in dispatch_request
    return self.view_functions[rule.endpoint](**req.view_args)
  File "/home/zetdg/Devasoft/devablog/.devablog/lib/python3.5/site-packages/flask_login/utils.py", line 261, in decorated_view
    return func(*args, **kwargs)
  File "/home/zetdg/Devasoft/devablog/app/routes.py", line 140, in follow
    flash("You are following {}!".format(username))
UnboundLocalError: local variable 'flash' referenced before assignment
2017-12-31 19:04:03,160 ERROR: Exception on /follow/vovo [GET] [in /home/zetdg/Devasoft/devablog/.devablog/lib/python3.5/site-packages/flask/app.py:1560]
Traceback (most recent call last):
  File "/home/zetdg/Devasoft/devablog/.devablog/lib/python3.5/site-packages/flask/app.py", line 1982, in wsgi_app
    response = self.full_dispatch_request()
  File "/home/zetdg/Devasoft/devablog/.devablog/lib/python3.5/site-packages/flask/app.py", line 1614, in full_dispatch_request
    rv = self.handle_user_exception(e)
  File "/home/zetdg/Devasoft/devablog/.devablog/lib/python3.5/site-packages/flask/app.py", line 1517, in handle_user_exception
    reraise(exc_type, exc_value, tb)
  File "/home/zetdg/Devasoft/devablog/.devablog/lib/python3.5/site-packages/flask/_compat.py", line 33, in reraise
    raise value
  File "/home/zetdg/Devasoft/devablog/.devablog/lib/python3.5/site-packages/flask/app.py", line 1612, in full_dispatch_request
    rv = self.dispatch_request()
  File "/home/zetdg/Devasoft/devablog/.devablog/lib/python3.5/site-packages/flask/app.py", line 1598, in dispatch_request
    return self.view_functions[rule.endpoint](**req.view_args)
  File "/home/zetdg/Devasoft/devablog/.devablog/lib/python3.5/site-packages/flask_login/utils.py", line 261, in decorated_view
    return func(*args, **kwargs)
  File "/home/zetdg/Devasoft/devablog/app/routes.py", line 140, in follow
    flash("You are following {}!".format(username))
UnboundLocalError: local variable 'flash' referenced before assignment
2017-12-31 19:06:15,929 ERROR: Exception on /follow/ze [GET] [in /home/zetdg/Devasoft/devablog/.devablog/lib/python3.5/site-packages/flask/app.py:1560]
Traceback (most recent call last):
  File "/home/zetdg/Devasoft/devablog/.devablog/lib/python3.5/site-packages/flask/app.py", line 1982, in wsgi_app
    response = self.full_dispatch_request()
  File "/home/zetdg/Devasoft/devablog/.devablog/lib/python3.5/site-packages/flask/app.py", line 1614, in full_dispatch_request
    rv = self.handle_user_exception(e)
  File "/home/zetdg/Devasoft/devablog/.devablog/lib/python3.5/site-packages/flask/app.py", line 1517, in handle_user_exception
    reraise(exc_type, exc_value, tb)
  File "/home/zetdg/Devasoft/devablog/.devablog/lib/python3.5/site-packages/flask/_compat.py", line 33, in reraise
    raise value
  File "/home/zetdg/Devasoft/devablog/.devablog/lib/python3.5/site-packages/flask/app.py", line 1612, in full_dispatch_request
    rv = self.dispatch_request()
  File "/home/zetdg/Devasoft/devablog/.devablog/lib/python3.5/site-packages/flask/app.py", line 1598, in dispatch_request
    return self.view_functions[rule.endpoint](**req.view_args)
  File "/home/zetdg/Devasoft/devablog/.devablog/lib/python3.5/site-packages/flask_login/utils.py", line 261, in decorated_view
    return func(*args, **kwargs)
  File "/home/zetdg/Devasoft/devablog/app/routes.py", line 140, in follow
    #flash("You are following {}!".format(username))
UnboundLocalError: local variable 'flash' referenced before assignment
2017-12-31 19:06:21,599 INFO: Devablog startup [in /home/zetdg/Devasoft/devablog/app/__init__.py:57]
2017-12-31 19:07:34,874 INFO: Devablog startup [in /home/zetdg/Devasoft/devablog/app/__init__.py:57]
2017-12-31 19:08:06,539 INFO: Devablog startup [in /home/zetdg/Devasoft/devablog/app/__init__.py:57]
2017-12-31 19:09:08,047 INFO: Devablog startup [in /home/zetdg/Devasoft/devablog/app/__init__.py:57]
2017-12-31 19:09:16,329 ERROR: Exception on /follow/vovo [GET] [in /home/zetdg/Devasoft/devablog/.devablog/lib/python3.5/site-packages/flask/app.py:1560]
Traceback (most recent call last):
  File "/home/zetdg/Devasoft/devablog/.devablog/lib/python3.5/site-packages/flask/app.py", line 1982, in wsgi_app
    response = self.full_dispatch_request()
  File "/home/zetdg/Devasoft/devablog/.devablog/lib/python3.5/site-packages/flask/app.py", line 1614, in full_dispatch_request
    rv = self.handle_user_exception(e)
  File "/home/zetdg/Devasoft/devablog/.devablog/lib/python3.5/site-packages/flask/app.py", line 1517, in handle_user_exception
    reraise(exc_type, exc_value, tb)
  File "/home/zetdg/Devasoft/devablog/.devablog/lib/python3.5/site-packages/flask/_compat.py", line 33, in reraise
    raise value
  File "/home/zetdg/Devasoft/devablog/.devablog/lib/python3.5/site-packages/flask/app.py", line 1612, in full_dispatch_request
    rv = self.dispatch_request()
  File "/home/zetdg/Devasoft/devablog/.devablog/lib/python3.5/site-packages/flask/app.py", line 1598, in dispatch_request
    return self.view_functions[rule.endpoint](**req.view_args)
  File "/home/zetdg/Devasoft/devablog/.devablog/lib/python3.5/site-packages/flask_login/utils.py", line 261, in decorated_view
    return func(*args, **kwargs)
  File "/home/zetdg/Devasoft/devablog/app/routes.py", line 141, in follow
    flash("Not following.")
UnboundLocalError: local variable 'flash' referenced before assignment
2017-12-31 19:16:00,004 INFO: Devablog startup [in /home/zetdg/Devasoft/devablog/app/__init__.py:57]
2017-12-31 19:25:56,218 INFO: Devablog startup [in /home/zetdg/Devasoft/devablog/app/__init__.py:57]
2017-12-31 19:51:58,038 INFO: Devablog startup [in /home/zetdg/Devasoft/devablog/app/__init__.py:57]
2017-12-31 19:52:47,663 INFO: Devablog startup [in /home/zetdg/Devasoft/devablog/app/__init__.py:57]
2017-12-31 19:53:13,703 INFO: Devablog startup [in /home/zetdg/Devasoft/devablog/app/__init__.py:57]
2017-12-31 19:53:40,898 INFO: Devablog startup [in /home/zetdg/Devasoft/devablog/app/__init__.py:57]
2017-12-31 19:53:53,300 INFO: Devablog startup [in /home/zetdg/Devasoft/devablog/app/__init__.py:57]
2017-12-31 19:54:20,633 INFO: Devablog startup [in /home/zetdg/Devasoft/devablog/app/__init__.py:57]
2017-12-31 19:57:27,581 INFO: Devablog startup [in /home/zetdg/Devasoft/devablog/app/__init__.py:57]
2017-12-31 19:59:21,593 INFO: Devablog startup [in /home/zetdg/Devasoft/devablog/app/__init__.py:57]
2017-12-31 19:59:46,093 INFO: Devablog startup [in /home/zetdg/Devasoft/devablog/app/__init__.py:57]
2017-12-31 19:59:56,060 INFO: Devablog startup [in /home/zetdg/Devasoft/devablog/app/__init__.py:57]
2017-12-31 20:00:29,081 INFO: Devablog startup [in /home/zetdg/Devasoft/devablog/app/__init__.py:57]
2017-12-31 20:00:41,880 INFO: Devablog startup [in /home/zetdg/Devasoft/devablog/app/__init__.py:57]
2017-12-31 20:00:50,494 INFO: Devablog startup [in /home/zetdg/Devasoft/devablog/app/__init__.py:57]
2017-12-31 20:02:26,731 INFO: Devablog startup [in /home/zetdg/Devasoft/devablog/app/__init__.py:57]
2017-12-31 20:52:28,084 INFO: Devablog startup [in /home/zetdg/Devasoft/devablog/app/__init__.py:57]
2017-12-31 20:53:30,826 INFO: Devablog startup [in /home/zetdg/Devasoft/devablog/app/__init__.py:57]
