2017-12-31 21:26:28,073 ERROR: Exception on /ze [GET] [in /home/zetdg/Devasoft/devablog/.devablog/lib/python3.5/site-packages/flask/app.py:1560]
Traceback (most recent call last):
  File "/home/zetdg/Devasoft/devablog/.devablog/lib/python3.5/site-packages/flask/app.py", line 1982, in wsgi_app
    response = self.full_dispatch_request()
  File "/home/zetdg/Devasoft/devablog/.devablog/lib/python3.5/site-packages/flask/app.py", line 1614, in full_dispatch_request
    rv = self.handle_user_exception(e)
  File "/home/zetdg/Devasoft/devablog/.devablog/lib/python3.5/site-packages/flask/app.py", line 1517, in handle_user_exception
    reraise(exc_type, exc_value, tb)
  File "/home/zetdg/Devasoft/devablog/.devablog/lib/python3.5/site-packages/flask/_compat.py", line 33, in reraise
    raise value
  File "/home/zetdg/Devasoft/devablog/.devablog/lib/python3.5/site-packages/flask/app.py", line 1612, in full_dispatch_request
    rv = self.dispatch_request()
  File "/home/zetdg/Devasoft/devablog/.devablog/lib/python3.5/site-packages/flask/app.py", line 1598, in dispatch_request
    return self.view_functions[rule.endpoint](**req.view_args)
  File "/home/zetdg/Devasoft/devablog/.devablog/lib/python3.5/site-packages/flask_login/utils.py", line 261, in decorated_view
    return func(*args, **kwargs)
  File "/home/zetdg/Devasoft/devablog/app/routes.py", line 88, in user
    next_url = url_for("user", page=posts.next_num) if posts.has_next else None
  File "/home/zetdg/Devasoft/devablog/.devablog/lib/python3.5/site-packages/flask/helpers.py", line 333, in url_for
    return appctx.app.handle_url_build_error(error, endpoint, values)
  File "/home/zetdg/Devasoft/devablog/.devablog/lib/python3.5/site-packages/flask/app.py", line 1805, in handle_url_build_error
    reraise(exc_type, exc_value, tb)
  File "/home/zetdg/Devasoft/devablog/.devablog/lib/python3.5/site-packages/flask/_compat.py", line 33, in reraise
    raise value
  File "/home/zetdg/Devasoft/devablog/.devablog/lib/python3.5/site-packages/flask/helpers.py", line 323, in url_for
    force_external=external)
  File "/home/zetdg/Devasoft/devablog/.devablog/lib/python3.5/site-packages/werkzeug/routing.py", line 1768, in build
    raise BuildError(endpoint, values, method, self)
werkzeug.routing.BuildError: Could not build url for endpoint 'user' with values ['page']. Did you forget to specify values ['username']?
2017-12-31 21:27:21,986 ERROR: Exception on /ze [GET] [in /home/zetdg/Devasoft/devablog/.devablog/lib/python3.5/site-packages/flask/app.py:1560]
Traceback (most recent call last):
  File "/home/zetdg/Devasoft/devablog/.devablog/lib/python3.5/site-packages/flask/app.py", line 1982, in wsgi_app
    response = self.full_dispatch_request()
  File "/home/zetdg/Devasoft/devablog/.devablog/lib/python3.5/site-packages/flask/app.py", line 1614, in full_dispatch_request
    rv = self.handle_user_exception(e)
  File "/home/zetdg/Devasoft/devablog/.devablog/lib/python3.5/site-packages/flask/app.py", line 1517, in handle_user_exception
    reraise(exc_type, exc_value, tb)
  File "/home/zetdg/Devasoft/devablog/.devablog/lib/python3.5/site-packages/flask/_compat.py", line 33, in reraise
    raise value
  File "/home/zetdg/Devasoft/devablog/.devablog/lib/python3.5/site-packages/flask/app.py", line 1612, in full_dispatch_request
    rv = self.dispatch_request()
  File "/home/zetdg/Devasoft/devablog/.devablog/lib/python3.5/site-packages/flask/app.py", line 1598, in dispatch_request
    return self.view_functions[rule.endpoint](**req.view_args)
  File "/home/zetdg/Devasoft/devablog/.devablog/lib/python3.5/site-packages/flask_login/utils.py", line 261, in decorated_view
    return func(*args, **kwargs)
  File "/home/zetdg/Devasoft/devablog/app/routes.py", line 88, in user
    next_url = url_for("user", page=posts.next_num) if posts.has_next else None
  File "/home/zetdg/Devasoft/devablog/.devablog/lib/python3.5/site-packages/flask/helpers.py", line 333, in url_for
    return appctx.app.handle_url_build_error(error, endpoint, values)
  File "/home/zetdg/Devasoft/devablog/.devablog/lib/python3.5/site-packages/flask/app.py", line 1805, in handle_url_build_error
    reraise(exc_type, exc_value, tb)
  File "/home/zetdg/Devasoft/devablog/.devablog/lib/python3.5/site-packages/flask/_compat.py", line 33, in reraise
    raise value
  File "/home/zetdg/Devasoft/devablog/.devablog/lib/python3.5/site-packages/flask/helpers.py", line 323, in url_for
    force_external=external)
  File "/home/zetdg/Devasoft/devablog/.devablog/lib/python3.5/site-packages/werkzeug/routing.py", line 1768, in build
    raise BuildError(endpoint, values, method, self)
werkzeug.routing.BuildError: Could not build url for endpoint 'user' with values ['page']. Did you forget to specify values ['username']?
2017-12-31 21:28:02,328 ERROR: Exception on /ze [GET] [in /home/zetdg/Devasoft/devablog/.devablog/lib/python3.5/site-packages/flask/app.py:1560]
Traceback (most recent call last):
  File "/home/zetdg/Devasoft/devablog/.devablog/lib/python3.5/site-packages/flask/app.py", line 1982, in wsgi_app
    response = self.full_dispatch_request()
  File "/home/zetdg/Devasoft/devablog/.devablog/lib/python3.5/site-packages/flask/app.py", line 1614, in full_dispatch_request
    rv = self.handle_user_exception(e)
  File "/home/zetdg/Devasoft/devablog/.devablog/lib/python3.5/site-packages/flask/app.py", line 1517, in handle_user_exception
    reraise(exc_type, exc_value, tb)
  File "/home/zetdg/Devasoft/devablog/.devablog/lib/python3.5/site-packages/flask/_compat.py", line 33, in reraise
    raise value
  File "/home/zetdg/Devasoft/devablog/.devablog/lib/python3.5/site-packages/flask/app.py", line 1612, in full_dispatch_request
    rv = self.dispatch_request()
  File "/home/zetdg/Devasoft/devablog/.devablog/lib/python3.5/site-packages/flask/app.py", line 1598, in dispatch_request
    return self.view_functions[rule.endpoint](**req.view_args)
  File "/home/zetdg/Devasoft/devablog/.devablog/lib/python3.5/site-packages/flask_login/utils.py", line 261, in decorated_view
    return func(*args, **kwargs)
  File "/home/zetdg/Devasoft/devablog/app/routes.py", line 88, in user
    next_url = url_for("user", page=posts.next_num) if posts.has_next else None
  File "/home/zetdg/Devasoft/devablog/.devablog/lib/python3.5/site-packages/flask/helpers.py", line 333, in url_for
    return appctx.app.handle_url_build_error(error, endpoint, values)
  File "/home/zetdg/Devasoft/devablog/.devablog/lib/python3.5/site-packages/flask/app.py", line 1805, in handle_url_build_error
    reraise(exc_type, exc_value, tb)
  File "/home/zetdg/Devasoft/devablog/.devablog/lib/python3.5/site-packages/flask/_compat.py", line 33, in reraise
    raise value
  File "/home/zetdg/Devasoft/devablog/.devablog/lib/python3.5/site-packages/flask/helpers.py", line 323, in url_for
    force_external=external)
  File "/home/zetdg/Devasoft/devablog/.devablog/lib/python3.5/site-packages/werkzeug/routing.py", line 1768, in build
    raise BuildError(endpoint, values, method, self)
werkzeug.routing.BuildError: Could not build url for endpoint 'user' with values ['page']. Did you forget to specify values ['username']?
2017-12-31 21:32:28,972 INFO: Devablog startup [in /home/zetdg/Devasoft/devablog/app/__init__.py:57]
2017-12-31 21:32:34,009 ERROR: Exception on /user/ze [GET] [in /home/zetdg/Devasoft/devablog/.devablog/lib/python3.5/site-packages/flask/app.py:1560]
Traceback (most recent call last):
  File "/home/zetdg/Devasoft/devablog/.devablog/lib/python3.5/site-packages/flask/app.py", line 1982, in wsgi_app
    response = self.full_dispatch_request()
  File "/home/zetdg/Devasoft/devablog/.devablog/lib/python3.5/site-packages/flask/app.py", line 1614, in full_dispatch_request
    rv = self.handle_user_exception(e)
  File "/home/zetdg/Devasoft/devablog/.devablog/lib/python3.5/site-packages/flask/app.py", line 1517, in handle_user_exception
    reraise(exc_type, exc_value, tb)
  File "/home/zetdg/Devasoft/devablog/.devablog/lib/python3.5/site-packages/flask/_compat.py", line 33, in reraise
    raise value
  File "/home/zetdg/Devasoft/devablog/.devablog/lib/python3.5/site-packages/flask/app.py", line 1612, in full_dispatch_request
    rv = self.dispatch_request()
  File "/home/zetdg/Devasoft/devablog/.devablog/lib/python3.5/site-packages/flask/app.py", line 1598, in dispatch_request
    return self.view_functions[rule.endpoint](**req.view_args)
  File "/home/zetdg/Devasoft/devablog/.devablog/lib/python3.5/site-packages/flask_login/utils.py", line 261, in decorated_view
    return func(*args, **kwargs)
  File "/home/zetdg/Devasoft/devablog/app/routes.py", line 88, in user
    next_url = url_for("user", page=posts.next_num) if posts.has_next else None
  File "/home/zetdg/Devasoft/devablog/.devablog/lib/python3.5/site-packages/flask/helpers.py", line 333, in url_for
    return appctx.app.handle_url_build_error(error, endpoint, values)
  File "/home/zetdg/Devasoft/devablog/.devablog/lib/python3.5/site-packages/flask/app.py", line 1805, in handle_url_build_error
    reraise(exc_type, exc_value, tb)
  File "/home/zetdg/Devasoft/devablog/.devablog/lib/python3.5/site-packages/flask/_compat.py", line 33, in reraise
    raise value
  File "/home/zetdg/Devasoft/devablog/.devablog/lib/python3.5/site-packages/flask/helpers.py", line 323, in url_for
    force_external=external)
  File "/home/zetdg/Devasoft/devablog/.devablog/lib/python3.5/site-packages/werkzeug/routing.py", line 1768, in build
    raise BuildError(endpoint, values, method, self)
werkzeug.routing.BuildError: Could not build url for endpoint 'user' with values ['page']. Did you forget to specify values ['username']?
