2017-12-31 16:20:41,745 ERROR: Exception on /edit_profile [POST] [in /home/zetdg/Devasoft/devablog/.devablog/lib/python3.5/site-packages/flask/app.py:1560]
Traceback (most recent call last):
  File "/home/zetdg/Devasoft/devablog/.devablog/lib/python3.5/site-packages/flask/app.py", line 1982, in wsgi_app
    response = self.full_dispatch_request()
  File "/home/zetdg/Devasoft/devablog/.devablog/lib/python3.5/site-packages/flask/app.py", line 1615, in full_dispatch_request
    return self.finalize_request(rv)
  File "/home/zetdg/Devasoft/devablog/.devablog/lib/python3.5/site-packages/flask/app.py", line 1630, in finalize_request
    response = self.make_response(rv)
  File "/home/zetdg/Devasoft/devablog/.devablog/lib/python3.5/site-packages/flask/app.py", line 1725, in make_response
    raise ValueError('View function did not return a response')
ValueError: View function did not return a response
2017-12-31 16:23:27,852 INFO: Devablog startup [in /home/zetdg/Devasoft/devablog/app/__init__.py:58]
2017-12-31 16:23:35,511 ERROR: Exception on /edit_profile [POST] [in /home/zetdg/Devasoft/devablog/.devablog/lib/python3.5/site-packages/flask/app.py:1560]
Traceback (most recent call last):
  File "/home/zetdg/Devasoft/devablog/.devablog/lib/python3.5/site-packages/flask/app.py", line 1982, in wsgi_app
    response = self.full_dispatch_request()
  File "/home/zetdg/Devasoft/devablog/.devablog/lib/python3.5/site-packages/flask/app.py", line 1615, in full_dispatch_request
    return self.finalize_request(rv)
  File "/home/zetdg/Devasoft/devablog/.devablog/lib/python3.5/site-packages/flask/app.py", line 1630, in finalize_request
    response = self.make_response(rv)
  File "/home/zetdg/Devasoft/devablog/.devablog/lib/python3.5/site-packages/flask/app.py", line 1725, in make_response
    raise ValueError('View function did not return a response')
ValueError: View function did not return a response
2017-12-31 16:58:10,804 INFO: Devablog startup [in /home/zetdg/Devasoft/devablog/app/__init__.py:58]
2017-12-31 16:58:14,259 INFO: Devablog startup [in /home/zetdg/Devasoft/devablog/app/__init__.py:58]
2017-12-31 17:17:24,794 INFO: Devablog startup [in /home/zetdg/Devasoft/devablog/app/__init__.py:58]
2017-12-31 17:19:31,578 INFO: Devablog startup [in /home/zetdg/Devasoft/devablog/app/__init__.py:58]
2017-12-31 17:20:04,750 INFO: Devablog startup [in /home/zetdg/Devasoft/devablog/app/__init__.py:58]
2017-12-31 17:20:51,747 INFO: Devablog startup [in /home/zetdg/Devasoft/devablog/app/__init__.py:58]
2017-12-31 17:21:36,210 INFO: Devablog startup [in /home/zetdg/Devasoft/devablog/app/__init__.py:58]
2017-12-31 18:56:58,938 INFO: Devablog startup [in /home/zetdg/Devasoft/devablog/app/__init__.py:58]
2017-12-31 18:57:31,797 ERROR: Exception on /user/ze [GET] [in /home/zetdg/Devasoft/devablog/.devablog/lib/python3.5/site-packages/flask/app.py:1560]
Traceback (most recent call last):
  File "/home/zetdg/Devasoft/devablog/.devablog/lib/python3.5/site-packages/flask/app.py", line 1982, in wsgi_app
    response = self.full_dispatch_request()
  File "/home/zetdg/Devasoft/devablog/.devablog/lib/python3.5/site-packages/flask/app.py", line 1614, in full_dispatch_request
    rv = self.handle_user_exception(e)
  File "/home/zetdg/Devasoft/devablog/.devablog/lib/python3.5/site-packages/flask/app.py", line 1517, in handle_user_exception
    reraise(exc_type, exc_value, tb)
  File "/home/zetdg/Devasoft/devablog/.devablog/lib/python3.5/site-packages/flask/_compat.py", line 33, in reraise
    raise value
  File "/home/zetdg/Devasoft/devablog/.devablog/lib/python3.5/site-packages/flask/app.py", line 1612, in full_dispatch_request
    rv = self.dispatch_request()
  File "/home/zetdg/Devasoft/devablog/.devablog/lib/python3.5/site-packages/flask/app.py", line 1598, in dispatch_request
    return self.view_functions[rule.endpoint](**req.view_args)
  File "/home/zetdg/Devasoft/devablog/.devablog/lib/python3.5/site-packages/flask_login/utils.py", line 261, in decorated_view
    return func(*args, **kwargs)
  File "/home/zetdg/Devasoft/devablog/app/routes.py", line 84, in user
    return render_template('user.html', user=user, posts=posts)
  File "/home/zetdg/Devasoft/devablog/.devablog/lib/python3.5/site-packages/flask/templating.py", line 134, in render_template
    context, ctx.app)
  File "/home/zetdg/Devasoft/devablog/.devablog/lib/python3.5/site-packages/flask/templating.py", line 116, in _render
    rv = template.render(context)
  File "/home/zetdg/Devasoft/devablog/.devablog/lib/python3.5/site-packages/jinja2/environment.py", line 1008, in render
    return self.environment.handle_exception(exc_info, True)
  File "/home/zetdg/Devasoft/devablog/.devablog/lib/python3.5/site-packages/jinja2/environment.py", line 780, in handle_exception
    reraise(exc_type, exc_value, tb)
  File "/home/zetdg/Devasoft/devablog/.devablog/lib/python3.5/site-packages/jinja2/_compat.py", line 37, in reraise
    raise value.with_traceback(tb)
  File "/home/zetdg/Devasoft/devablog/app/templates/user.html", line 1, in top-level template code
    {% extends "base.html" %}
  File "/home/zetdg/Devasoft/devablog/app/templates/base.html", line 43, in top-level template code
    {% block content %}{% endblock %}
  File "/home/zetdg/Devasoft/devablog/app/templates/user.html", line 18, in block "content"
    {% elif not current_user.isfollowing(user) %}
jinja2.exceptions.UndefinedError: 'app.models.User object' has no attribute 'isfollowing'
2017-12-31 18:57:40,885 ERROR: Exception on /user/winne [GET] [in /home/zetdg/Devasoft/devablog/.devablog/lib/python3.5/site-packages/flask/app.py:1560]
Traceback (most recent call last):
  File "/home/zetdg/Devasoft/devablog/.devablog/lib/python3.5/site-packages/flask/app.py", line 1982, in wsgi_app
    response = self.full_dispatch_request()
  File "/home/zetdg/Devasoft/devablog/.devablog/lib/python3.5/site-packages/flask/app.py", line 1614, in full_dispatch_request
    rv = self.handle_user_exception(e)
  File "/home/zetdg/Devasoft/devablog/.devablog/lib/python3.5/site-packages/flask/app.py", line 1517, in handle_user_exception
    reraise(exc_type, exc_value, tb)
  File "/home/zetdg/Devasoft/devablog/.devablog/lib/python3.5/site-packages/flask/_compat.py", line 33, in reraise
    raise value
  File "/home/zetdg/Devasoft/devablog/.devablog/lib/python3.5/site-packages/flask/app.py", line 1612, in full_dispatch_request
    rv = self.dispatch_request()
  File "/home/zetdg/Devasoft/devablog/.devablog/lib/python3.5/site-packages/flask/app.py", line 1598, in dispatch_request
    return self.view_functions[rule.endpoint](**req.view_args)
  File "/home/zetdg/Devasoft/devablog/.devablog/lib/python3.5/site-packages/flask_login/utils.py", line 261, in decorated_view
    return func(*args, **kwargs)
  File "/home/zetdg/Devasoft/devablog/app/routes.py", line 84, in user
    return render_template('user.html', user=user, posts=posts)
  File "/home/zetdg/Devasoft/devablog/.devablog/lib/python3.5/site-packages/flask/templating.py", line 134, in render_template
    context, ctx.app)
  File "/home/zetdg/Devasoft/devablog/.devablog/lib/python3.5/site-packages/flask/templating.py", line 116, in _render
    rv = template.render(context)
  File "/home/zetdg/Devasoft/devablog/.devablog/lib/python3.5/site-packages/jinja2/environment.py", line 1008, in render
    return self.environment.handle_exception(exc_info, True)
  File "/home/zetdg/Devasoft/devablog/.devablog/lib/python3.5/site-packages/jinja2/environment.py", line 780, in handle_exception
    reraise(exc_type, exc_value, tb)
  File "/home/zetdg/Devasoft/devablog/.devablog/lib/python3.5/site-packages/jinja2/_compat.py", line 37, in reraise
    raise value.with_traceback(tb)
  File "/home/zetdg/Devasoft/devablog/app/templates/user.html", line 1, in top-level template code
    {% extends "base.html" %}
  File "/home/zetdg/Devasoft/devablog/app/templates/base.html", line 43, in top-level template code
    {% block content %}{% endblock %}
  File "/home/zetdg/Devasoft/devablog/app/templates/user.html", line 18, in block "content"
    {% elif not current_user.isfollowing(user) %}
jinja2.exceptions.UndefinedError: 'app.models.User object' has no attribute 'isfollowing'
2017-12-31 18:57:56,448 INFO: Devablog startup [in /home/zetdg/Devasoft/devablog/app/__init__.py:58]
2017-12-31 18:58:00,390 ERROR: Exception on /follow/winne [GET] [in /home/zetdg/Devasoft/devablog/.devablog/lib/python3.5/site-packages/flask/app.py:1560]
Traceback (most recent call last):
  File "/home/zetdg/Devasoft/devablog/.devablog/lib/python3.5/site-packages/flask/app.py", line 1982, in wsgi_app
    response = self.full_dispatch_request()
  File "/home/zetdg/Devasoft/devablog/.devablog/lib/python3.5/site-packages/flask/app.py", line 1614, in full_dispatch_request
    rv = self.handle_user_exception(e)
  File "/home/zetdg/Devasoft/devablog/.devablog/lib/python3.5/site-packages/flask/app.py", line 1517, in handle_user_exception
    reraise(exc_type, exc_value, tb)
  File "/home/zetdg/Devasoft/devablog/.devablog/lib/python3.5/site-packages/flask/_compat.py", line 33, in reraise
    raise value
  File "/home/zetdg/Devasoft/devablog/.devablog/lib/python3.5/site-packages/flask/app.py", line 1612, in full_dispatch_request
    rv = self.dispatch_request()
  File "/home/zetdg/Devasoft/devablog/.devablog/lib/python3.5/site-packages/flask/app.py", line 1598, in dispatch_request
    return self.view_functions[rule.endpoint](**req.view_args)
  File "/home/zetdg/Devasoft/devablog/.devablog/lib/python3.5/site-packages/flask_login/utils.py", line 261, in decorated_view
    return func(*args, **kwargs)
  File "/home/zetdg/Devasoft/devablog/app/routes.py", line 140, in follow
    flash("You are following {}!".format(username))
UnboundLocalError: local variable 'flash' referenced before assignment
2017-12-31 19:01:59,438 INFO: Devablog startup [in /home/zetdg/Devasoft/devablog/app/__init__.py:57]
